Workbook

Sheet Dashboard
A1: Teach Yourself CS — Progress Dashboard
A2: Subjects are in study order (theory block, then systems block). Every budget includes a 10-hour fallback-lecture reserve. All numbers here are calculated from the subject sheets.
B4: Overall complete | D4: Hours done | F4: Hours planned | H4: Actual hours logged | J4: Problems done | L4: Labs/projects done
B5: =F17 -> 0.019128142 | D5: =E17 -> 29.75 | F5: =D17 -> 1555.3 | H5: =K17 -> 24 | J5: =H17 -> 21 | L5: =J17 -> 0
A7: # | B7: Subject | C7: Resources | D7: Planned hrs | E7: Done hrs | F7: % complete | G7: Problems planned | H7: Problems done | I7: Labs/projects planned | J7: Labs/projects done | K7: Actual hrs | L7: Started | M7: Last activity | N7: Status
A8: 1 | B8: Programming | C8: SICP 2nd ed., Ch 1–3 | D8: =SUM('1 Programming'!$G$6:$G$500)-SUMIFS('1 Programming'!$G$6:$G$500,'1 Programming'!$H$6:$H$500,"Skipped") -> 180.25 | E8: =SUMIFS('1 Programming'!$G$6:$G$500,'1 Programming'!$H$6:$H$500,"Done") -> 29.75 | F8: =IF(D8=0,0,E8/D8) -> 0.16504854 | G8: =SUMIFS('1 Programming'!$E$6:$E$500,'1 Programming'!$D$6:$D$500,"Exercise")-SUMIFS('1 Programming'!$E$6:$E$500,'1 Programming'!$D$6:$D$500,"Exercise",'1 Programming'!$H$6:$H$500,"Skipped") -> 124 | H8: =SUMIFS('1 Programming'!$E$6:$E$500,'1 Programming'!$D$6:$D$500,"Exercise",'1 Programming'!$H$6:$H$500,"Done") -> 21 | I8: =COUNTIFS('1 Programming'!$D$6:$D$500,"Lab/Project")-COUNTIFS('1 Programming'!$D$6:$D$500,"Lab/Project",'1 Programming'!$H$6:$H$500,"Skipped") -> 0 | J8: =COUNTIFS('1 Programming'!$D$6:$D$500,"Lab/Project",'1 Programming'!$H$6:$H$500,"Done") -> 0 | K8: =SUM('1 Programming'!$J$6:$J$500) -> 24 | L8: =IF(COUNT('1 Programming'!$I$6:$I$500)=0,"",MIN('1 Programming'!$I$6:$I$500)) -> 46288 | M8: =IF(COUNT('1 Programming'!$I$6:$I$500)=0,"",MAX('1 Programming'!$I$6:$I$500)) -> 46318 | N8: =IF(AND(D8>0,E8>=D8-0.001),"Complete",IF(OR(E8>0,COUNTIF('1 Programming'!$H$6:$H$500,"In progress")>0),"In progress","Not started")) -> In progress
A9: 2 | B9: Math for CS | C9: MCS (2018 PDF), core chapters | D9: =SUM('2 Math for CS'!$G$6:$G$500)-SUMIFS('2 Math for CS'!$G$6:$G$500,'2 Math for CS'!$H$6:$H$500,"Skipped") -> 167 | E9: =SUMIFS('2 Math for CS'!$G$6:$G$500,'2 Math for CS'!$H$6:$H$500,"Done") -> 0 | F9: =IF(D9=0,0,E9/D9) -> 0 | G9: =SUMIFS('2 Math for CS'!$E$6:$E$500,'2 Math for CS'!$D$6:$D$500,"Exercise")-SUMIFS('2 Math for CS'!$E$6:$E$500,'2 Math for CS'!$D$6:$D$500,"Exercise",'2 Math for CS'!$H$6:$H$500,"Skipped") -> 125 | H9: =SUMIFS('2 Math for CS'!$E$6:$E$500,'2 Math for CS'!$D$6:$D$500,"Exercise",'2 Math for CS'!$H$6:$H$500,"Done") -> 0 | I9: =COUNTIFS('2 Math for CS'!$D$6:$D$500,"Lab/Project")-COUNTIFS('2 Math for CS'!$D$6:$D$500,"Lab/Project",'2 Math for CS'!$H$6:$H$500,"Skipped") -> 0 | J9: =COUNTIFS('2 Math for CS'!$D$6:$D$500,"Lab/Project",'2 Math for CS'!$H$6:$H$500,"Done") -> 0 | K9: =SUM('2 Math for CS'!$J$6:$J$500) -> 0 | L9: =IF(COUNT('2 Math for CS'!$I$6:$I$500)=0,"",MIN('2 Math for CS'!$I$6:$I$500)) | M9: =IF(COUNT('2 Math for CS'!$I$6:$I$500)=0,"",MAX('2 Math for CS'!$I$6:$I$500)) | N9: =IF(AND(D9>0,E9>=D9-0.001),"Complete",IF(OR(E9>0,COUNTIF('2 Math for CS'!$H$6:$H$500,"In progress")>0),"In progress","Not started")) -> Not started
A10: 3 | B10: Algorithms | C10: ADM 3rd ed. Part I + 100 LeetCode | D10: =SUM('3 Algorithms'!$G$6:$G$500)-SUMIFS('3 Algorithms'!$G$6:$G$500,'3 Algorithms'!$H$6:$H$500,"Skipped") -> 177.05 | E10: =SUMIFS('3 Algorithms'!$G$6:$G$500,'3 Algorithms'!$H$6:$H$500,"Done") -> 0 | F10: =IF(D10=0,0,E10/D10) -> 0 | G10: =SUMIFS('3 Algorithms'!$E$6:$E$500,'3 Algorithms'!$D$6:$D$500,"Exercise")-SUMIFS('3 Algorithms'!$E$6:$E$500,'3 Algorithms'!$D$6:$D$500,"Exercise",'3 Algorithms'!$H$6:$H$500,"Skipped") -> 150 | H10: =SUMIFS('3 Algorithms'!$E$6:$E$500,'3 Algorithms'!$D$6:$D$500,"Exercise",'3 Algorithms'!$H$6:$H$500,"Done") -> 0 | I10: =COUNTIFS('3 Algorithms'!$D$6:$D$500,"Lab/Project")-COUNTIFS('3 Algorithms'!$D$6:$D$500,"Lab/Project",'3 Algorithms'!$H$6:$H$500,"Skipped") -> 0 | J10: =COUNTIFS('3 Algorithms'!$D$6:$D$500,"Lab/Project",'3 Algorithms'!$H$6:$H$500,"Done") -> 0 | K10: =SUM('3 Algorithms'!$J$6:$J$500) -> 0 | L10: =IF(COUNT('3 Algorithms'!$I$6:$I$500)=0,"",MIN('3 Algorithms'!$I$6:$I$500)) | M10: =IF(COUNT('3 Algorithms'!$I$6:$I$500)=0,"",MAX('3 Algorithms'!$I$6:$I$500)) | N10: =IF(AND(D10>0,E10>=D10-0.001),"Complete",IF(OR(E10>0,COUNTIF('3 Algorithms'!$H$6:$H$500,"In progress")>0),"In progress","Not started")) -> Not started
A11: 4 | B11: Computer Architecture | C11: CS:APP 3rd ed. (NA), Ch 1–6 + 4 labs | D11: =SUM('4 Architecture'!$G$6:$G$500)-SUMIFS('4 Architecture'!$G$6:$G$500,'4 Architecture'!$H$6:$H$500,"Skipped") -> 183.8 | E11: =SUMIFS('4 Architecture'!$G$6:$G$500,'4 Architecture'!$H$6:$H$500,"Done") -> 0 | F11: =IF(D11=0,0,E11/D11) -> 0 | G11: =SUMIFS('4 Architecture'!$E$6:$E$500,'4 Architecture'!$D$6:$D$500,"Exercise")-SUMIFS('4 Architecture'!$E$6:$E$500,'4 Architecture'!$D$6:$D$500,"Exercise",'4 Architecture'!$H$6:$H$500,"Skipped") -> 219 | H11: =SUMIFS('4 Architecture'!$E$6:$E$500,'4 Architecture'!$D$6:$D$500,"Exercise",'4 Architecture'!$H$6:$H$500,"Done") -> 0 | I11: =COUNTIFS('4 Architecture'!$D$6:$D$500,"Lab/Project")-COUNTIFS('4 Architecture'!$D$6:$D$500,"Lab/Project",'4 Architecture'!$H$6:$H$500,"Skipped") -> 4 | J11: =COUNTIFS('4 Architecture'!$D$6:$D$500,"Lab/Project",'4 Architecture'!$H$6:$H$500,"Done") -> 0 | K11: =SUM('4 Architecture'!$J$6:$J$500) -> 0 | L11: =IF(COUNT('4 Architecture'!$I$6:$I$500)=0,"",MIN('4 Architecture'!$I$6:$I$500)) | M11: =IF(COUNT('4 Architecture'!$I$6:$I$500)=0,"",MAX('4 Architecture'!$I$6:$I$500)) | N11: =IF(AND(D11>0,E11>=D11-0.001),"Complete",IF(OR(E11>0,COUNTIF('4 Architecture'!$H$6:$H$500,"In progress")>0),"In progress","Not started")) -> Not started
A12: 5 | B12: Languages & Compilers | C12: Nand2Tetris Part II + Crafting Interpreters | D12: =SUM('5 Lang & Compilers'!$G$6:$G$500)-SUMIFS('5 Lang & Compilers'!$G$6:$G$500,'5 Lang & Compilers'!$H$6:$H$500,"Skipped") -> 178 | E12: =SUMIFS('5 Lang & Compilers'!$G$6:$G$500,'5 Lang & Compilers'!$H$6:$H$500,"Done") -> 0 | F12: =IF(D12=0,0,E12/D12) -> 0 | G12: =SUMIFS('5 Lang & Compilers'!$E$6:$E$500,'5 Lang & Compilers'!$D$6:$D$500,"Exercise")-SUMIFS('5 Lang & Compilers'!$E$6:$E$500,'5 Lang & Compilers'!$D$6:$D$500,"Exercise",'5 Lang & Compilers'!$H$6:$H$500,"Skipped") -> 12 | H12: =SUMIFS('5 Lang & Compilers'!$E$6:$E$500,'5 Lang & Compilers'!$D$6:$D$500,"Exercise",'5 Lang & Compilers'!$H$6:$H$500,"Done") -> 0 | I12: =COUNTIFS('5 Lang & Compilers'!$D$6:$D$500,"Lab/Project")-COUNTIFS('5 Lang & Compilers'!$D$6:$D$500,"Lab/Project",'5 Lang & Compilers'!$H$6:$H$500,"Skipped") -> 6 | J12: =COUNTIFS('5 Lang & Compilers'!$D$6:$D$500,"Lab/Project",'5 Lang & Compilers'!$H$6:$H$500,"Done") -> 0 | K12: =SUM('5 Lang & Compilers'!$J$6:$J$500) -> 0 | L12: =IF(COUNT('5 Lang & Compilers'!$I$6:$I$500)=0,"",MIN('5 Lang & Compilers'!$I$6:$I$500)) | M12: =IF(COUNT('5 Lang & Compilers'!$I$6:$I$500)=0,"",MAX('5 Lang & Compilers'!$I$6:$I$500)) | N12: =IF(AND(D12>0,E12>=D12-0.001),"Complete",IF(OR(E12>0,COUNTIF('5 Lang & Compilers'!$H$6:$H$500,"In progress")>0),"In progress","Not started")) -> Not started
A13: 6 | B13: Operating Systems | C13: OSTEP (all) + MIT 6.1810 labs | D13: =SUM('6 Operating Systems'!$G$6:$G$500)-SUMIFS('6 Operating Systems'!$G$6:$G$500,'6 Operating Systems'!$H$6:$H$500,"Skipped") -> 168.5 | E13: =SUMIFS('6 Operating Systems'!$G$6:$G$500,'6 Operating Systems'!$H$6:$H$500,"Done") -> 0 | F13: =IF(D13=0,0,E13/D13) -> 0 | G13: =SUMIFS('6 Operating Systems'!$E$6:$E$500,'6 Operating Systems'!$D$6:$D$500,"Exercise")-SUMIFS('6 Operating Systems'!$E$6:$E$500,'6 Operating Systems'!$D$6:$D$500,"Exercise",'6 Operating Systems'!$H$6:$H$500,"Skipped") -> 26 | H13: =SUMIFS('6 Operating Systems'!$E$6:$E$500,'6 Operating Systems'!$D$6:$D$500,"Exercise",'6 Operating Systems'!$H$6:$H$500,"Done") -> 0 | I13: =COUNTIFS('6 Operating Systems'!$D$6:$D$500,"Lab/Project")-COUNTIFS('6 Operating Systems'!$D$6:$D$500,"Lab/Project",'6 Operating Systems'!$H$6:$H$500,"Skipped") -> 6 | J13: =COUNTIFS('6 Operating Systems'!$D$6:$D$500,"Lab/Project",'6 Operating Systems'!$H$6:$H$500,"Done") -> 0 | K13: =SUM('6 Operating Systems'!$J$6:$J$500) -> 0 | L13: =IF(COUNT('6 Operating Systems'!$I$6:$I$500)=0,"",MIN('6 Operating Systems'!$I$6:$I$500)) | M13: =IF(COUNT('6 Operating Systems'!$I$6:$I$500)=0,"",MAX('6 Operating Systems'!$I$6:$I$500)) | N13: =IF(AND(D13>0,E13>=D13-0.001),"Complete",IF(OR(E13>0,COUNTIF('6 Operating Systems'!$H$6:$H$500,"In progress")>0),"In progress","Not started")) -> Not started
A14: 7 | B14: Computer Networking | C14: Kurose & Ross 9th ed. + Wireshark 9.0 | D14: =SUM('7 Networking'!$G$6:$G$500)-SUMIFS('7 Networking'!$G$6:$G$500,'7 Networking'!$H$6:$H$500,"Skipped") -> 164.5 | E14: =SUMIFS('7 Networking'!$G$6:$G$500,'7 Networking'!$H$6:$H$500,"Done") -> 0 | F14: =IF(D14=0,0,E14/D14) -> 0 | G14: =SUMIFS('7 Networking'!$E$6:$E$500,'7 Networking'!$D$6:$D$500,"Exercise")-SUMIFS('7 Networking'!$E$6:$E$500,'7 Networking'!$D$6:$D$500,"Exercise",'7 Networking'!$H$6:$H$500,"Skipped") -> 119 | H14: =SUMIFS('7 Networking'!$E$6:$E$500,'7 Networking'!$D$6:$D$500,"Exercise",'7 Networking'!$H$6:$H$500,"Done") -> 0 | I14: =COUNTIFS('7 Networking'!$D$6:$D$500,"Lab/Project")-COUNTIFS('7 Networking'!$D$6:$D$500,"Lab/Project",'7 Networking'!$H$6:$H$500,"Skipped") -> 17 | J14: =COUNTIFS('7 Networking'!$D$6:$D$500,"Lab/Project",'7 Networking'!$H$6:$H$500,"Done") -> 0 | K14: =SUM('7 Networking'!$J$6:$J$500) -> 0 | L14: =IF(COUNT('7 Networking'!$I$6:$I$500)=0,"",MIN('7 Networking'!$I$6:$I$500)) | M14: =IF(COUNT('7 Networking'!$I$6:$I$500)=0,"",MAX('7 Networking'!$I$6:$I$500)) | N14: =IF(AND(D14>0,E14>=D14-0.001),"Complete",IF(OR(E14>0,COUNTIF('7 Networking'!$H$6:$H$500,"In progress")>0),"In progress","Not started")) -> Not started
A15: 8 | B15: Databases | C15: CMU 15-445 + DSC 7th ed. + BusTub | D15: =SUM('8 Databases'!$G$6:$G$500)-SUMIFS('8 Databases'!$G$6:$G$500,'8 Databases'!$H$6:$H$500,"Skipped") -> 169.2 | E15: =SUMIFS('8 Databases'!$G$6:$G$500,'8 Databases'!$H$6:$H$500,"Done") -> 0 | F15: =IF(D15=0,0,E15/D15) -> 0 | G15: =SUMIFS('8 Databases'!$E$6:$E$500,'8 Databases'!$D$6:$D$500,"Exercise")-SUMIFS('8 Databases'!$E$6:$E$500,'8 Databases'!$D$6:$D$500,"Exercise",'8 Databases'!$H$6:$H$500,"Skipped") -> 43 | H15: =SUMIFS('8 Databases'!$E$6:$E$500,'8 Databases'!$D$6:$D$500,"Exercise",'8 Databases'!$H$6:$H$500,"Done") -> 0 | I15: =COUNTIFS('8 Databases'!$D$6:$D$500,"Lab/Project")-COUNTIFS('8 Databases'!$D$6:$D$500,"Lab/Project",'8 Databases'!$H$6:$H$500,"Skipped") -> 4 | J15: =COUNTIFS('8 Databases'!$D$6:$D$500,"Lab/Project",'8 Databases'!$H$6:$H$500,"Done") -> 0 | K15: =SUM('8 Databases'!$J$6:$J$500) -> 0 | L15: =IF(COUNT('8 Databases'!$I$6:$I$500)=0,"",MIN('8 Databases'!$I$6:$I$500)) | M15: =IF(COUNT('8 Databases'!$I$6:$I$500)=0,"",MAX('8 Databases'!$I$6:$I$500)) | N15: =IF(AND(D15>0,E15>=D15-0.001),"Complete",IF(OR(E15>0,COUNTIF('8 Databases'!$H$6:$H$500,"In progress")>0),"In progress","Not started")) -> Not started
A16: 9 | B16: Distributed Systems | C16: DDIA 2nd ed. + Gossip Glomers + 6.5840 | D16: =SUM('9 Distributed'!$G$6:$G$500)-SUMIFS('9 Distributed'!$G$6:$G$500,'9 Distributed'!$H$6:$H$500,"Skipped") -> 167 | E16: =SUMIFS('9 Distributed'!$G$6:$G$500,'9 Distributed'!$H$6:$H$500,"Done") -> 0 | F16: =IF(D16=0,0,E16/D16) -> 0 | G16: =SUMIFS('9 Distributed'!$E$6:$E$500,'9 Distributed'!$D$6:$D$500,"Exercise")-SUMIFS('9 Distributed'!$E$6:$E$500,'9 Distributed'!$D$6:$D$500,"Exercise",'9 Distributed'!$H$6:$H$500,"Skipped") -> 0 | H16: =SUMIFS('9 Distributed'!$E$6:$E$500,'9 Distributed'!$D$6:$D$500,"Exercise",'9 Distributed'!$H$6:$H$500,"Done") -> 0 | I16: =COUNTIFS('9 Distributed'!$D$6:$D$500,"Lab/Project")-COUNTIFS('9 Distributed'!$D$6:$D$500,"Lab/Project",'9 Distributed'!$H$6:$H$500,"Skipped") -> 12 | J16: =COUNTIFS('9 Distributed'!$D$6:$D$500,"Lab/Project",'9 Distributed'!$H$6:$H$500,"Done") -> 0 | K16: =SUM('9 Distributed'!$J$6:$J$500) -> 0 | L16: =IF(COUNT('9 Distributed'!$I$6:$I$500)=0,"",MIN('9 Distributed'!$I$6:$I$500)) | M16: =IF(COUNT('9 Distributed'!$I$6:$I$500)=0,"",MAX('9 Distributed'!$I$6:$I$500)) | N16: =IF(AND(D16>0,E16>=D16-0.001),"Complete",IF(OR(E16>0,COUNTIF('9 Distributed'!$H$6:$H$500,"In progress")>0),"In progress","Not started")) -> Not started
B17: Total | D17: =SUM(D8:D16) -> 1555.3 | E17: =SUM(E8:E16) -> 29.75 | F17: =IF(D17=0,0,E17/D17) -> 0.019128142 | G17: =SUM(G8:G16) -> 818 | H17: =SUM(H8:H16) -> 21 | I17: =SUM(I8:I16) -> 49 | J17: =SUM(J8:J16) -> 0 | K17: =SUM(K8:K16) -> 24 | L17: =IF(COUNT(L8:L16)=0,"",MIN(L8:L16)) -> 46288 | M17: =IF(COUNT(M8:M16)=0,"",MAX(M8:M16)) -> 46318 | N17: =COUNTIF(N8:N16,"Complete")&" of 9 complete" -> 0 of 9 complete

Sheet Guide
A1: How this plan works
A3: HOW TO USE
A4: Order | B4: Work the subject sheets in number order and each sheet top to bottom; rows are sequenced so reading comes right before its exercises.
A5: Cells you edit | B5: Only the shaded columns on subject sheets: Status (dropdown), Date done, Actual hrs, Notes. Everything else, including the Dashboard, is calculated.
A6: Status | B6: Not started / In progress / Done / Skipped. Done rows turn green and count toward progress. Skipped removes a row from the planned totals.
A7: Multi-problem rows | B7: Rows like "Ch 5 problems ×10" give a count and a selection rule. Mark Done when you've finished that many, and write the problem numbers you chose in Notes.
A8: Reserve rows | B8: Each subject has a 10-hour "Fallback lectures reserve". Log any lecture time in Actual hrs and mark it Done when the subject is finished.
A9: Progress math | B9: % complete = estimated hours of Done rows ÷ planned hours, so a 14-hour lab moves the needle more than a 15-minute exercise.
A11: EXAMPLE ROW
A12: Filled-in example | B12: #: 18 | Chapter / Section: 1.2 | Item: Ex 1.19 | Type: Exercise | Qty: 1 | What & why: Logarithmic Fibonacci (T_pq) | Est. hrs: 1.5 | Status: Done | Date done: 2026-11-03 | Actual hrs: 2.0 | Notes: Needed a hint for p' and q'
A14: RULES BEHIND THE LISTS
A15: Hours over percentage | B15: Budgets are 150–200 hours per subject. SICP hits 55% of its exercises; books with hundreds of problems (MCS, CS:APP, ADM, Kurose & Ross) get the highest-yield subset that fits the hours.
A16: Exact vs. rule-based rows | B16: SICP, CS:APP homework, OSTEP homework chapters, Crafting Interpreters challenges, the Kurose & Ross interactive problems and Wireshark labs are listed by number or name. MCS, ADM, Kurose & Ross textbook problems and Database System Concepts practice exercises are per-chapter counts with a selection rule, because I couldn't verify those books' exact numbering.
A17: Labs count as exercises | B17: Labs and projects often replace end-of-chapter problems where they teach the same thing better (e.g. Data Lab replaces most CS:APP Ch 2 bit-puzzle homework).
A18: Lectures | B18: Fallback only: watch a lecture when a topic doesn't click after reading and one or two exercises.
A20: CHECKING YOUR WORK
A21: SICP | B21: community.schemewiki.org (sicp-solutions pages)
A22: MCS | B22: No official answer key; write proofs out in full and have them critiqued.
A23: ADM | B23: Odd-numbered solutions: algorist.com/algowiki
A24: CS:APP | B24: Practice-problem solutions at the end of each chapter; lab handouts include self-checking tools.
A25: OSTEP | B25: Homework simulators print answers with the -c flag.
A26: Kurose & Ross | B26: Interactive problems show solutions; Wireshark lab solutions are instructor-only.
A27: Crafting Interpreters | B27: Challenge answers in the book repo's note/answers folder.
A28: Databases | B28: Practice-exercise solutions on db-book.com; BusTub ships local tests.
A29: 6.1810 / 6.5840 | B29: make grade (6.1810) and the provided Go test suites (6.5840).
A31: CROSS-SUBJECT DEDUPLICATION
A32: Proofs & recurrences | B32: Done in MCS, so ADM Ch 1–2 and 5 exercises skip induction, summation, and recurrence-solving.
A33: RSA | B33: Done in MCS Ch 9; skim it in Kurose & Ross Ch 8 and OSTEP's cryptography chapter.
A34: Concurrency | B34: SICP 3.4 is kept to three exercises; OSTEP covers it properly.
A35: Compilers | B35: Crafting Interpreters Ch 4, 16, 22–24 are skimmed because N2T II projects 8, 10, 11 cover them.
A36: Storage & transactions | B36: 15-445 comes first, so DDIA's B-tree/LSM and single-node isolation sections are skims.
A37: Distributed | B37: OSTEP's distribution chapters are read-only; DDIA and 6.5840 go deeper.
A39: LANGUAGE RAMPS (inside budgets)
A40: C | B40: Start of Architecture (10 h). Used again in clox, OSTEP, and 6.1810.
A41: Java | B41: Before jlox in Languages & Compilers (4 h).
A42: C++ | B42: BusTub Project 0 in Databases.
A43: Go | B43: A Tour of Go at the start of Distributed Systems (5 h).
A45: EDITIONS & LINKS
A46: SICP | B46: 2nd ed. (Scheme). sarabander.github.io/sicp
A47: MCS | B47: Lehman, Leighton & Meyer, spring 2018 PDF: courses.csail.mit.edu/6.042/spring18/mcs.pdf. Chapter numbers follow that PDF; match by title if yours differs.
...

Sheet 1 Programming
A1: 1 · Programming — SICP 2nd ed., Ch 1–3
A2: SICP 2nd edition (Scheme), Chapters 1–3: 124 of 225 exercises (55%). Community solutions to check against: community.schemewiki.org (search sicp-solutions).
A3: Planned hrs | B3: =SUM($G$6:$G$500)-SUMIFS($G$6:$G$500,$H$6:$H$500,"Skipped") -> 180.25 | C3: Done hrs | D3: =SUMIFS($G$6:$G$500,$H$6:$H$500,"Done") -> 29.75 | E3: % complete | F3: =IF(B3=0,0,D3/B3) -> 0.16504854 | G3: Problems done | H3: =SUMIFS($E$6:$E$500,$D$6:$D$500,"Exercise",$H$6:$H$500,"Done") -> 21 | I3: of | J3: =SUMIFS($E$6:$E$500,$D$6:$D$500,"Exercise")-SUMIFS($E$6:$E$500,$D$6:$D$500,"Exercise",$H$6:$H$500,"Skipped") -> 124
A5: # | B5: Chapter / Section | C5: Item | D5: Type | E5: Qty | F5: What & why | G5: Est. hrs | H5: Status | I5: Date done | J5: Actual hrs | K5: Notes
A6: 1 | B6: Setup | C6: Racket + #lang sicp | D6: Setup | F6: Install Racket, run `raco pkg install sicp`, use #lang sicp. Bookmark Brian Harvey's CS 61A lectures as the fallback. | G6: 2 | H6: Done | I6: 46295 | J6: 0.5
A7: 2 | B7: 1.1 | C7: Read §1.1 The Elements of Programming | D7: Reading | G7: 4 | H7: Done | I7: 46288 | J7: 2
A8: 3 | B8: 1.1 | C8: Ex 1.5 | D8: Exercise | E8: 1 | F8: Applicative vs. normal order (Ben's test) | G8: 0.5 | H8: Done | I8: 46288 | J8: 0.5
A9: 4 | B9: 1.1 | C9: Ex 1.6 | D9: Exercise | E9: 1 | F9: Why new-if recurses forever (special forms) | G9: 0.5 | H9: Done | I9: 46289 | J9: 0.5
A10: 5 | B10: 1.1 | C10: Ex 1.7 | D10: Exercise | E10: 1 | F10: good-enough? for tiny and huge numbers | G10: 1 | H10: Done | I10: 46290 | J10: 1
A11: 6 | B11: 1.1 | C11: Ex 1.8 | D11: Exercise | E11: 1 | F11: Cube roots by Newton's method | G11: 0.75 | H11: Done | I11: 46291 | J11: 1
A12: 7 | B12: 1.2 | C12: Read §1.2 Procedures and the Processes They Generate | D12: Reading | G12: 6 | H12: Done | I12: 46308 | J12: 5
A13: 8 | B13: 1.2 | C13: Ex 1.9 | D13: Exercise | E13: 1 | F13: Recursive vs. iterative process for + | G13: 0.5 | H13: Done | I13: 46293 | J13: 0.5
A14: 9 | B14: 1.2 | C14: Ex 1.11 | D14: Exercise | E14: 1 | F14: f(n) recursively and iteratively | G14: 1 | H14: Done | I14: 46293 | J14: 0.75
A15: 10 | B15: 1.2 | C15: Ex 1.14 | D15: Exercise | E15: 1 | F15: count-change tree; orders of growth | G15: 1.5 | H15: Done | I15: 46294 | J15: 1.5
A16: 11 | B16: 1.2 | C16: Ex 1.16 | D16: Exercise | E16: 1 | F16: Iterative fast-expt with an invariant | G16: 1 | H16: Done | I16: 46300 | J16: 1
A17: 12 | B17: 1.2 | C17: Ex 1.18 | D17: Exercise | E17: 1 | F17: Log-time iterative multiplication (uses 1.17's double/halve) | G17: 0.75 | H17: Done | I17: 46301 | J17: 1
A18: 13 | B18: 1.2 | C18: Ex 1.19 | D18: Exercise | E18: 1 | F18: Logarithmic Fibonacci (T_pq) | G18: 1.5 | H18: Done | I18: 46304 | J18: 1
A19: 14 | B19: 1.2 | C19: Ex 1.20 | D19: Exercise | E19: 1 | F19: GCD remainder count: normal vs. applicative order | G19: 1 | H19: Done | I19: 46304 | J19: 0.5
A20: 15 | B20: 1.2 | C20: Ex 1.22 | D20: Exercise | E20: 1 | F20: timed-prime-test; check the sqrt(10) growth claim | G20: 1 | H20: Done | I20: 46305 | J20: 1
A21: 16 | B21: 1.2 | C21: Ex 1.25 | D21: Exercise | E21: 1 | F21: Why not expmod via fast-expt? | G21: 0.5 | H21: Done | I21: 46305 | J21: 0.5
A22: 17 | B22: 1.2 | C22: Ex 1.26 | D22: Exercise | E22: 1 | F22: Louis's expmod: Θ(log n) becomes Θ(n) | G22: 0.5 | H22: Done | I22: 46306 | J22: 0.5
A23: 18 | B23: 1.2 | C23: Ex 1.27 | D23: Exercise | E23: 1 | F23: Carmichael numbers fool the Fermat test | G23: 0.75 | H23: Done | I23: 46306 | J23: 0.75
A24: 19 | B24: 1.2 | C24: Ex 1.28 | D24: Exercise | E24: 1 | F24: Miller–Rabin test | G24: 1.5 | H24: Done | I24: 46308 | J24: 1.5
A25: 20 | B25: 1.3 | C25: Read §1.3 Higher-Order Procedures | D25: Reading | G25: 4 | H25: In progress
A26: 21 | B26: 1.3 | C26: Ex 1.29 | D26: Exercise | E26: 1 | F26: Simpson's rule | G26: 1 | H26: Done | I26: 46312 | J26: 1
A27: 22 | B27: 1.3 | C27: Ex 1.30 | D27: Exercise | E27: 1 | F27: Iterative sum | G27: 0.5 | H27: Done | I27: 46312 | J27: 0.5
A28: 23 | B28: 1.3 | C28: Ex 1.32 | D28: Exercise | E28: 1 | F28: accumulate (recursive and iterative) | G28: 1 | H28: Done | I28: 46312 | J28: 0.5
A29: 24 | B29: 1.3 | C29: Ex 1.33 | D29: Exercise | E29: 1 | F29: filtered-accumulate | G29: 0.75 | H29: Done | I29: 46313 | J29: 0.75
A30: 25 | B30: 1.3 | C30: Ex 1.34 | D30: Exercise | E30: 1 | F30: What happens with (f f)? | G30: 0.25 | H30: Done | I30: 46318 | J30: 0.25
A31: 26 | B31: 1.3 | C31: Ex 1.35 | D31: Exercise | E31: 1 | F31: Golden ratio as a fixed point | G31: 0.5 | H31: In progress
A32: 27 | B32: 1.3 | C32: Ex 1.37 | D32: Exercise | E32: 1 | F32: cont-frac (recursive and iterative) | G32: 1 | H32: Not started
A33: 28 | B33: 1.3 | C33: Ex 1.40 | D33: Exercise | E33: 1 | F33: cubic for newtons-method | G33: 0.5 | H33: Not started
A34: 29 | B34: 1.3 | C34: Ex 1.41 | D34: Exercise | E34: 1 | F34: double; (((double (double double)) inc) 5) | G34: 0.75 | H34: Not started
A35: 30 | B35: 1.3 | C35: Ex 1.42 | D35: Exercise | E35: 1 | F35: compose | G35: 0.25 | H35: Not started
A36: 31 | B36: 1.3 | C36: Ex 1.43 | D36: Exercise | E36: 1 | F36: repeated | G36: 0.5 | H36: Not started
A37: 32 | B37: 1.3 | C37: Ex 1.45 | D37: Exercise | E37: 1 | F37: nth roots: how many average damps? | G37: 1.5 | H37: Not started
A38: 33 | B38: 1.3 | C38: Ex 1.46 | D38: Exercise | E38: 1 | F38: iterative-improve; rewrite sqrt and fixed-point | G38: 1 | H38: Not started
A39: 34 | B39: 2.1 | C39: Read §2.1 Introduction to Data Abstraction | D39: Reading | G39: 3 | H39: Not started
A40: 35 | B40: 2.1 | C40: Ex 2.2 | D40: Exercise | E40: 1 | F40: Segments, points, midpoint | G40: 0.5 | H40: Not started
A41: 36 | B41: 2.1 | C41: Ex 2.3 | D41: Exercise | E41: 1 | F41: Rectangles, two representations (abstraction barriers) | G41: 1 | H41: Not started
...

Sheet 2 Math for CS
A1: 2 · Math for CS — MCS (2018 PDF), core chapters
A2: Mathematics for Computer Science (Lehman, Leighton & Meyer). Problems sit at the end of each chapter, grouped by section and type (Practice / Class / Homework / Exam). Rows give a count and a rule rather than numbers. Skipped: Ch 11, 13, 16, 21 and §8.3–8.4.
A3: Planned hrs | B3: =SUM($G$6:$G$500)-SUMIFS($G$6:$G$500,$H$6:$H$500,"Skipped") -> 167 | C3: Done hrs | D3: =SUMIFS($G$6:$G$500,$H$6:$H$500,"Done") -> 0 | E3: % complete | F3: =IF(B3=0,0,D3/B3) -> 0 | G3: Problems done | H3: =SUMIFS($E$6:$E$500,$D$6:$D$500,"Exercise",$H$6:$H$500,"Done") -> 0 | I3: of | J3: =SUMIFS($E$6:$E$500,$D$6:$D$500,"Exercise")-SUMIFS($E$6:$E$500,$D$6:$D$500,"Exercise",$H$6:$H$500,"Skipped") -> 125
A5: # | B5: Chapter / Section | C5: Item | D5: Type | E5: Qty | F5: What & why | G5: Est. hrs | H5: Status | I5: Date done | J5: Actual hrs | K5: Notes
A6: 1 | B6: Setup | C6: Get the MCS PDF | D6: Setup | F6: courses.csail.mit.edu/6.042/spring18/mcs.pdf. Fallback videos: MIT 6.042J Fall 2010 (Leighton). | G6: 0.5 | H6: Not started
A7: 2 | B7: Ch 1 | C7: Read Ch 1: What is a Proof? | D7: Reading | G7: 3 | H7: Not started
A8: 3 | B8: Ch 1 | C8: Ch 1 problems ×7 | D8: Exercise | E8: 7 | F8: Implications, iff, cases, contradiction. Rule: all Practice problems for the sections you read, then Class problems up to the count. Log numbers in Notes. | G8: 5 | H8: Not started
A9: 4 | B9: Ch 2 | C9: Read Ch 2: The Well Ordering Principle | D9: Reading | G9: 2 | H9: Not started
A10: 5 | B10: Ch 2 | C10: Ch 2 problems ×3 | D10: Exercise | E10: 3 | F10: Use the WOP proof template. Rule: all Practice problems for the sections you read, then Class problems up to the count. Log numbers in Notes. | G10: 2.5 | H10: Not started
A11: 6 | B11: Ch 3 | C11: Read Ch 3: Logical Formulas | D11: Reading | G11: 3 | H11: Not started
A12: 7 | B12: Ch 3 | C12: Ch 3 problems ×6 | D12: Exercise | E12: 6 | F12: Equivalence, validity vs. satisfiability, predicate formulas. Rule: all Practice problems for the sections you read, then Class problems up to the count. Log numbers in Notes. | G12: 4.5 | H12: Not started
A13: 8 | B13: Ch 4 | C13: Read Ch 4: Mathematical Data Types | D13: Reading | G13: 3 | H13: Not started
A14: 9 | B14: Ch 4 | C14: Ch 4 problems ×7 | D14: Exercise | E14: 7 | F14: Functions and relations (surjective/injective/bijective), finite cardinality. Rule: all Practice problems for the sections you read, then Class problems up to the count. Log numbers in Notes. | G14: 5 | H14: Not started
A15: 10 | B15: Ch 5 | C15: Read Ch 5: Induction | D15: Reading | G15: 3 | H15: Not started
A16: 11 | B16: Ch 5 | C16: Ch 5 problems ×10 | D16: Exercise | E16: 10 | F16: At least 4 ordinary, 4 strong, and one find-the-flaw problem. Rule: all Practice problems for the sections you read, then Class problems up to the count. Log numbers in Notes. | G16: 8 | H16: Not started
A17: 12 | B17: Ch 6 | C17: Read Ch 6: State Machines | D17: Reading | G17: 3 | H17: Not started
A18: 13 | B18: Ch 6 | C18: Ch 6 problems ×6 | D18: Exercise | E18: 6 | F18: Invariant Principle, partial correctness and termination, stable matching. Rule: all Practice problems for the sections you read, then Class problems up to the count. Log numbers in Notes. | G18: 5 | H18: Not started
A19: 14 | B19: Ch 7 | C19: Read Ch 7: Recursive Data Types | D19: Reading | G19: 3 | H19: Not started
A20: 15 | B20: Ch 7 | C20: Ch 7 problems ×7 | D20: Exercise | E20: 7 | F20: Structural induction on strings and expressions (echoes SICP's deriv). Rule: all Practice problems for the sections you read, then Class problems up to the count. Log numbers in Notes. | G20: 6 | H20: Not started
A21: 16 | B21: Ch 8 | C21: Read Ch 8: Infinite Sets (§8.1–8.2 only) | D21: Reading | G21: 1.5 | H21: Not started
A22: 17 | B22: Ch 8 | C22: Ch 8 problems ×2 | D22: Exercise | E22: 2 | F22: Diagonal argument and the halting problem. Rule: all Practice problems for the sections you read, then Class problems up to the count. Log numbers in Notes. | G22: 1.5 | H22: Not started
A23: 18 | B23: Ch 9 | C23: Read Ch 9: Number Theory | D23: Reading | G23: 6 | H23: Not started
A24: 19 | B24: Ch 9 | C24: Ch 9 problems ×12 | D24: Exercise | E24: 12 | F24: Euclid/Pulverizer, inverses mod n, Euler's theorem, RSA end to end. Rule: all Practice problems for the sections you read, then Class problems up to the count. Log numbers in Notes. | G24: 9.5 | H24: Not started
A25: 20 | B25: Ch 10 | C25: Read Ch 10: Directed Graphs & Partial Orders | D25: Reading | G25: 4 | H25: Not started
A26: 21 | B26: Ch 10 | C26: Ch 10 problems ×8 | D26: Exercise | E26: 8 | F26: DAG scheduling and critical paths, partial orders, equivalence relations. Rule: all Practice problems for the sections you read, then Class problems up to the count. Log numbers in Notes. | G26: 6 | H26: Not started
A27: 22 | B27: Ch 12 | C27: Read Ch 12: Simple Graphs | D27: Reading | G27: 5 | H27: Not started
A28: 23 | B28: Ch 12 | C28: Ch 12 problems ×10 | D28: Exercise | E28: 10 | F28: Handshake lemma, matchings (Hall), coloring, connectivity, trees. Rule: all Practice problems for the sections you read, then Class problems up to the count. Log numbers in Notes. | G28: 8 | H28: Not started
A29: 24 | B29: Ch 14 | C29: Read Ch 14: Sums and Asymptotics | D29: Reading | G29: 4 | H29: Not started
A30: 25 | B30: Ch 14 | C30: Ch 14 problems ×7 | D30: Exercise | E30: 7 | F30: Closed forms, integral bounds, asymptotic-notation proofs. Rule: all Practice problems for the sections you read, then Class problems up to the count. Log numbers in Notes. | G30: 5.5 | H30: Not started
A31: 26 | B31: Ch 15 | C31: Read Ch 15: Cardinality Rules | D31: Reading | G31: 5 | H31: Not started
A32: 27 | B32: Ch 15 | C32: Ch 15 problems ×12 | D32: Exercise | E32: 12 | F32: Bijection and division rules, pigeonhole, inclusion–exclusion, combinatorial proofs. Rule: all Practice problems for the sections you read, then Class problems up to the count. Log numbers in Notes. | G32: 9 | H32: Not started
A33: 28 | B33: Ch 17 | C33: Read Ch 17: Events and Probability Spaces | D33: Reading | G33: 2 | H33: Not started
A34: 29 | B34: Ch 17 | C34: Ch 17 problems ×4 | D34: Exercise | E34: 4 | F34: Four-step method, birthday principle. Rule: all Practice problems for the sections you read, then Class problems up to the count. Log numbers in Notes. | G34: 3 | H34: Not started
A35: 30 | B35: Ch 18 | C35: Read Ch 18: Conditional Probability | D35: Reading | G35: 3 | H35: Not started
A36: 31 | B36: Ch 18 | C36: Ch 18 problems ×7 | D36: Exercise | E36: 7 | F36: Tree diagrams, total probability, Bayes, independence. Rule: all Practice problems for the sections you read, then Class problems up to the count. Log numbers in Notes. | G36: 5 | H36: Not started
A37: 32 | B37: Ch 19 | C37: Read Ch 19: Random Variables | D37: Reading | G37: 3 | H37: Not started
A38: 33 | B38: Ch 19 | C38: Ch 19 problems ×6 | D38: Exercise | E38: 6 | F38: Distributions, linearity of expectation. Rule: all Practice problems for the sections you read, then Class problems up to the count. Log numbers in Notes. | G38: 4.5 | H38: Not started
A39: 34 | B39: Ch 20 | C39: Read Ch 20: Deviation from the Mean | D39: Reading | G39: 3 | H39: Not started
A40: 35 | B40: Ch 20 | C40: Ch 20 problems ×6 | D40: Exercise | E40: 6 | F40: Markov, Chebyshev, sampling, Chernoff. Rule: all Practice problems for the sections you read, then Class problems up to the count. Log numbers in Notes. | G40: 5 | H40: Not started
A41: 36 | B41: Ch 22 | C41: Read Ch 22: Recurrences | D41: Reading | G41: 3 | H41: Not started
...

Sheet 3 Algorithms
A1: 3 · Algorithms — ADM 3rd ed. Part I + 100 LeetCode
A2: The Algorithm Design Manual, 3rd ed. Exercise rows are a count per chapter: pick odd-numbered ones so you can check against the solution wiki. The 100 LeetCode problems are grouped by chapter; if a chapter's own LeetCode list names a different problem, swap it in for one of that chapter's picks.
A3: Planned hrs | B3: =SUM($G$6:$G$500)-SUMIFS($G$6:$G$500,$H$6:$H$500,"Skipped") -> 177.05 | C3: Done hrs | D3: =SUMIFS($G$6:$G$500,$H$6:$H$500,"Done") -> 0 | E3: % complete | F3: =IF(B3=0,0,D3/B3) -> 0 | G3: Problems done | H3: =SUMIFS($E$6:$E$500,$D$6:$D$500,"Exercise",$H$6:$H$500,"Done") -> 0 | I3: of | J3: =SUMIFS($E$6:$E$500,$D$6:$D$500,"Exercise")-SUMIFS($E$6:$E$500,$D$6:$D$500,"Exercise",$H$6:$H$500,"Skipped") -> 150
A5: # | B5: Chapter / Section | C5: Item | D5: Type | E5: Qty | F5: What & why | G5: Est. hrs | H5: Status | I5: Date done | J5: Actual hrs | K5: Notes
A6: 1 | B6: Ch 1 | C6: Read Ch 1: Introduction to Algorithm Design | D6: Reading | G6: 3 | H6: Not started
A7: 2 | B7: Ch 1 | C7: Ch 1 exercises ×5 | D7: Exercise | E7: 5 | F7: Counterexamples, proofs of correctness, estimation. Skip induction/summation (done in MCS). Pick odd-numbered ones (worked solutions on algorist.com/algowiki). Log numbers in Notes. | G7: 4.5 | H7: Not started
A8: 3 | B8: Ch 2 | C8: Read Ch 2: Algorithm Analysis | D8: Reading | G8: 3 | H8: Not started
A9: 4 | B9: Ch 2 | C9: Ch 2 exercises ×3 | D9: Exercise | E9: 3 | F9: Big-Oh dominance and loop analysis only; MCS covered the math. Pick odd-numbered ones (worked solutions on algorist.com/algowiki). Log numbers in Notes. | G9: 2.7 | H9: Not started
A10: 5 | B10: Ch 3 | C10: Read Ch 3: Data Structures | D10: Reading | G10: 4 | H10: Not started
A11: 6 | B11: Ch 3 | C11: Ch 3 exercises ×5 | D11: Exercise | E11: 5 | F11: Design a structure for a stated mix of operations. Pick odd-numbered ones (worked solutions on algorist.com/algowiki). Log numbers in Notes. | G11: 4.5 | H11: Not started
A12: 7 | B12: Ch 3 | C12: LC 206: Reverse Linked List | D12: Exercise | E12: 1 | F12: LeetCode (Easy) | G12: 0.4 | H12: Not started
A13: 8 | B13: Ch 3 | C13: LC 21: Merge Two Sorted Lists | D13: Exercise | E13: 1 | F13: LeetCode (Easy) | G13: 0.4 | H13: Not started
A14: 9 | B14: Ch 3 | C14: LC 141: Linked List Cycle | D14: Exercise | E14: 1 | F14: LeetCode (Easy) | G14: 0.4 | H14: Not started
A15: 10 | B15: Ch 3 | C15: LC 19: Remove Nth Node From End of List | D15: Exercise | E15: 1 | F15: LeetCode (Medium) | G15: 0.75 | H15: Not started
A16: 11 | B16: Ch 3 | C16: LC 143: Reorder List | D16: Exercise | E16: 1 | F16: LeetCode (Medium) | G16: 0.75 | H16: Not started
A17: 12 | B17: Ch 3 | C17: LC 20: Valid Parentheses | D17: Exercise | E17: 1 | F17: LeetCode (Easy) | G17: 0.4 | H17: Not started
A18: 13 | B18: Ch 3 | C18: LC 155: Min Stack | D18: Exercise | E18: 1 | F18: LeetCode (Easy) | G18: 0.4 | H18: Not started
A19: 14 | B19: Ch 3 | C19: LC 232: Implement Queue using Stacks | D19: Exercise | E19: 1 | F19: LeetCode (Easy) | G19: 0.4 | H19: Not started
A20: 15 | B20: Ch 3 | C20: LC 150: Evaluate Reverse Polish Notation | D20: Exercise | E20: 1 | F20: LeetCode (Medium) | G20: 0.75 | H20: Not started
A21: 16 | B21: Ch 3 | C21: LC 739: Daily Temperatures | D21: Exercise | E21: 1 | F21: LeetCode (Medium) | G21: 0.75 | H21: Not started
A22: 17 | B22: Ch 3 | C22: LC 84: Largest Rectangle in Histogram | D22: Exercise | E22: 1 | F22: LeetCode (Hard) | G22: 1.25 | H22: Not started
... A30: 25 | B30: Ch 3 | C30: LC 208: Implement Trie (Prefix Tree) | D30: Exercise | E30: 1 | F30: LeetCode (Medium) | G30: 0.75 | H30: Not started
A31: 26 | B31: Ch 4 | C31: Read Ch 4: Sorting | D31: Reading | G31: 3.5 | H31: Not started
A32: 27 | B32: Ch 4 | C32: Ch 4 exercises ×5 | D32: Exercise | E32: 5 | F32: Sorting as a tool: applications and interview problems. Pick odd-numbered ones (worked solutions on algorist.com/algowiki). Log numbers in Notes. | G32: 4.5 | H32: Not started
A33: 28 | B33: Ch 4 | C33: LC 88: Merge Sorted Array | D33: Exercise | E33: 1 | F33: LeetCode (Easy) | G33: 0.4 | H33: Not started
A34: 29 | B34: Ch 4 | C34: LC 56: Merge Intervals | D34: Exercise | E34: 1 | F34: LeetCode (Medium) | G34: 0.75 | H34: Not started
A35: 30 | B35: Ch 4 | C35: LC 57: Insert Interval | D35: Exercise | E35: 1 | F35: LeetCode (Medium) | G35: 0.75 | H35: Not started
A36: 31 | B36: Ch 4 | C36: LC 75: Sort Colors | D36: Exercise | E36: 1 | F36: LeetCode (Medium) | G36: 0.75 | H36: Not started
A37: 32 | B37: Ch 4 | C37: LC 215: Kth Largest Element in an Array | D37: Exercise | E37: 1 | F37: LeetCode (Medium) | G37: 0.75 | H37: Not started
A38: 33 | B38: Ch 4 | C38: LC 703: Kth Largest Element in a Stream | D38: Exercise | E38: 1 | F38: LeetCode (Easy) | G38: 0.4 | H38: Not started
A39: 34 | B39: Ch 4 | C39: LC 347: Top K Frequent Elements | D39: Exercise | E39: 1 | F39: LeetCode (Medium) | G39: 0.75 | H39: Not started
A40: 35 | B40: Ch 4 | C40: LC 973: K Closest Points to Origin | D40: Exercise | E40: 1 | F40: LeetCode (Medium) | G40: 0.75 | H40: Not started
A41: 36 | B41: Ch 4 | C41: LC 23: Merge k Sorted Lists | D41: Exercise | E41: 1 | F41: LeetCode (Hard) | G41: 1.25 | H41: Not started
A42: 37 | B42: Ch 4 | C42: LC 295: Find Median from Data Stream | D42: Exercise | E42: 1 | F42: LeetCode (Hard) | G42: 1.25 | H42: Not started
A43: 38 | B43: Ch 4 | C43: LC 148: Sort List | D43: Exercise | E43: 1 | F43: LeetCode (Medium) | G43: 0.75 | H43: Not started
... A45: 40 | B45: Ch 4 | C45: LC 179: Largest Number | D45: Exercise | E45: 1 | F45: LeetCode (Medium) | G45: 0.75 | H45: Not started
A46: 41 | B46: Ch 5 | C46: Read Ch 5: Divide and Conquer | D46: Reading | G46: 3 | H46: Not started
A47: 42 | B47: Ch 5 | C47: Ch 5 exercises ×4 | D47: Exercise | E47: 4 | F47: Binary-search variants and D&C design; recurrences were done in MCS. Pick odd-numbered ones (worked solutions on algorist.com/algowiki). Log numbers in Notes. | G47: 3.6 | H47: Not started
A48: 43 | B48: Ch 5 | C48: LC 704: Binary Search | D48: Exercise | E48: 1 | F48: LeetCode (Easy) | G48: 0.4 | H48: Not started
A49: 44 | B49: Ch 5 | C49: LC 35: Search Insert Position | D49: Exercise | E49: 1 | F49: LeetCode (Easy) | G49: 0.4 | H49: Not started
...

Sheet 4 Architecture
A1: 4 · Computer Architecture — CS:APP 3rd ed. (NA), Ch 1–6 + 4 labs
A2: Computer Systems: A Programmer's Perspective, 3rd ed., North American. Homework numbers are for that edition; if one doesn't match its description, go by the description. Lab self-study handouts: csapp.cs.cmu.edu/3e/labs.html.
A3: Planned hrs | B3: =SUM($G$6:$G$500)-SUMIFS($G$6:$G$500,$H$6:$H$500,"Skipped") -> 183.8 | C3: Done hrs | D3: =SUMIFS($G$6:$G$500,$H$6:$H$500,"Done") -> 0 | E3: % complete | F3: =IF(B3=0,0,D3/B3) -> 0 | G3: Problems done | H3: =SUMIFS($E$6:$E$500,$D$6:$D$500,"Exercise",$H$6:$H$500,"Done") -> 0 | I3: of | J3: =SUMIFS($E$6:$E$500,$D$6:$D$500,"Exercise")-SUMIFS($E$6:$E$500,$D$6:$D$500,"Exercise",$H$6:$H$500,"Skipped") -> 219
A5: # | B5: Chapter / Section | C5: Item | D5: Type | E5: Qty | F5: What & why | G5: Est. hrs | H5: Status | I5: Date done | J5: Actual hrs | K5: Notes
A6: 1 | B6: Setup | C6: C ramp | D6: Setup | F6: Beej's Guide to C or K&R C ch. 1–6: pointers, arrays, structs, malloc, a few small programs. | G6: 10 | H6: Not started
A7: 2 | B7: Setup | C7: x86-64 Linux environment | D7: Setup | F7: Labs need x86-64 Linux (native, VM, or Docker). Install gcc, gdb, make. | G7: 2 | H7: Not started
A8: 3 | B8: Ch 1 | C8: Read Ch 1: A Tour of Computer Systems | D8: Reading | G8: 2 | H8: Not started
A9: 4 | B9: Ch 1 | C9: Practice problems 1.1–1.2 | D9: Exercise | E9: 2 | F9: Amdahl's law. | G9: 0.3 | H9: Not started
A10: 5 | B10: Ch 2 | C10: Read Ch 2: Representing and Manipulating Information | D10: Reading | G10: 11 | H10: Not started
A11: 6 | B11: Ch 2 | C11: Practice problems 2.1–2.54 | D11: Exercise | E11: 54 | F11: Do them inline as you read; solutions are at the end of the chapter. | G11: 9 | H11: Not started
A12: 7 | B12: Ch 2 | C12: Data Lab | D12: Lab/Project | F12: Bit-level puzzles with restricted operators; covers much of the Ch 2 homework. | G12: 10 | H12: Not started
A13: 8 | B13: Ch 2 | C13: Ex 2.65 | D13: Exercise | E13: 1 | F13: odd_ones (parity in ≤12 ops) | G13: 1.5 | H13: Not started
A14: 9 | B14: Ch 2 | C14: Ex 2.73 | D14: Exercise | E14: 1 | F14: saturating_add | G14: 1 | H14: Not started
A15: 10 | B15: Ch 2 | C15: Ex 2.75 | D15: Exercise | E15: 1 | F15: unsigned_high_prod | G15: 1 | H15: Not started
A16: 11 | B16: Ch 2 | C16: Ex 2.78 | D16: Exercise | E16: 1 | F16: divide_power2 (round toward zero) | G16: 0.75 | H16: Not started
A17: 12 | B17: Ch 2 | C17: Ex 2.82 | D17: Exercise | E17: 1 | F17: Which int expressions are always true? | G17: 0.75 | H17: Not started
A18: 13 | B18: Ch 2 | C18: Ex 2.84 | D18: Exercise | E18: 1 | F18: float_le | G18: 0.75 | H18: Not started
A19: 14 | B19: Ch 2 | C19: Ex 2.89 | D19: Exercise | E19: 1 | F19: Which double expressions are always true? | G19: 0.75 | H19: Not started
A20: 15 | B20: Ch 3 | C20: Read Ch 3: Machine-Level Representation of Programs | D20: Reading | G20: 14 | H20: Not started
A21: 16 | B21: Ch 3 | C21: Practice problems 3.1–3.57 | D21: Exercise | E21: 57 | F21: Inline; solutions at the end of the chapter. | G21: 10 | H21: Not started
A22: 17 | B22: Ch 3 | C22: Bomb Lab | D22: Lab/Project | F22: Reverse-engineer a binary with gdb. | G22: 11 | H22: Not started
A23: 18 | B23: Ch 3 | C23: Attack Lab | D23: Lab/Project | F23: Code injection and return-oriented programming. | G23: 10 | H23: Not started
A24: 19 | B24: Ch 3 | C24: Ex 3.60 | D24: Exercise | E24: 1 | F24: Reconstruct loop() from assembly | G24: 1 | H24: Not started
A25: 20 | B25: Ch 3 | C25: Ex 3.63 | D25: Exercise | E25: 1 | F25: Reconstruct a switch from its jump table | G25: 1 | H25: Not started
A26: 21 | B26: Ch 3 | C26: Ex 3.67 | D26: Exercise | E26: 1 | F26: Passing and returning structs (eval/process) | G26: 1.5 | H26: Not started
A27: 22 | B27: Ch 3 | C27: Ex 3.69 | D27: Exercise | E27: 1 | F27: Infer a_struct and CNT | G27: 1 | H27: Not started
A28: 23 | B28: Ch 3 | C28: Ex 3.72 | D28: Exercise | E28: 1 | F28: Stack frame with alloca | G28: 1 | H28: Not started
A29: 24 | B29: Ch 4 | C29: Read Ch 4: Processor Architecture | D29: Reading | G29: 11 | H29: Not started
A30: 25 | B30: Ch 4 | C30: All Ch 4 practice problems (4.1 up to 4.44) | D30: Exercise | E30: 44 | F30: Inline; solutions at the end of the chapter. | G30: 7 | H30: Not started
A31: 26 | B31: Ch 4 | C31: Ex 4.47 | D31: Exercise | E31: 1 | F31: Bubble sort in Y86-64 | G31: 1.5 | H31: Not started
A32: 27 | B32: Ch 4 | C32: Ex 4.51 | D32: Exercise | E32: 1 | F32: iaddq: stage-by-stage computations | G32: 0.75 | H32: Not started
A33: 28 | B33: Ch 4 | C33: Ex 4.52 | D33: Exercise | E33: 1 | F33: Implement iaddq in seq-full.hcl | G33: 1.5 | H33: Not started
A34: 29 | B34: Ch 4 | C34: Ex 4.53 | D34: Exercise | E34: 1 | F34: Pipeline with stalling instead of forwarding | G34: 2 | H34: Not started
A35: 30 | B35: Ch 4 | C35: Ex 4.54 | D35: Exercise | E35: 1 | F35: Implement iaddq in pipe-full.hcl | G35: 1.5 | H35: Not started
A36: 31 | B36: Ch 4 | C36: Ex 4.56 | D36: Exercise | E36: 1 | F36: Backward-taken/forward-not-taken prediction | G36: 1.5 | H36: Not started
A37: 32 | B37: Ch 5 | C37: Read Ch 5: Optimizing Program Performance | D37: Reading | G37: 7 | H37: Not started
A38: 33 | B38: Ch 5 | C38: Practice problems 5.1–5.12 | D38: Exercise | E38: 12 | F38: Inline; solutions at the end of the chapter. | G38: 2.5 | H38: Not started
A39: 34 | B39: Ch 5 | C39: Ex 5.13 | D39: Exercise | E39: 1 | F39: Data-flow analysis of an inner product | G39: 1 | H39: Not started
A40: 35 | B40: Ch 5 | C40: Ex 5.14 | D40: Exercise | E40: 1 | F40: 6×1 loop unrolling | G40: 1 | H40: Not started
A41: 36 | B41: Ch 5 | C41: Ex 5.15 | D41: Exercise | E41: 1 | F41: 6×6 unrolling | G41: 1 | H41: Not started
...

Sheet 5 Lang & Compilers
A1: 5 · Languages & Compilers — Nand2Tetris Part II + Crafting Interpreters
A2: Nand2Tetris Part II (The Elements of Computing Systems 2e, Ch 7–12) in Python, then Crafting Interpreters minus the overlap. SKIM rows: read fast, then copy that chapter's finished code from github.com/munificent/craftinginterpreters, since each chapter builds on the last.
A3: Planned hrs | B3: =SUM($G$6:$G$500)-SUMIFS($G$6:$G$500,$H$6:$H$500,"Skipped") -> 178 | C3: Done hrs | D3: =SUMIFS($G$6:$G$500,$H$6:$H$500,"Done") -> 0 | E3: % complete | F3: =IF(B3=0,0,D3/B3) -> 0 | G3: Problems done | H3: =SUMIFS($E$6:$E$500,$D$6:$D$500,"Exercise",$H$6:$H$500,"Done") -> 0 | I3: of | J3: =SUMIFS($E$6:$E$500,$D$6:$D$500,"Exercise")-SUMIFS($E$6:$E$500,$D$6:$D$500,"Exercise",$H$6:$H$500,"Skipped") -> 12
A5: # | B5: Chapter / Section | C5: Item | D5: Type | E5: Qty | F5: What & why | G5: Est. hrs | H5: Status | I5: Date done | J5: Actual hrs | K5: Notes
A6: 1 | B6: Setup | C6: N2T tools + Python project skeleton | D6: Setup | F6: Download the Nand2Tetris software suite (VM emulator, CPU emulator). Write your translator and compiler in Python. | G6: 1 | H6: Not started
A7: 2 | B7: N2T 7 | C7: Read TECS 2e Ch 7: Virtual Machine I: Processing | D7: Reading | G7: 2 | H7: Not started
A8: 3 | B8: N2T 7 | C8: Project 7 | D8: Lab/Project | F8: VM translator I: stack arithmetic and memory segments → Hack assembly | G8: 8 | H8: Not started
A9: 4 | B9: N2T 8 | C9: Read TECS 2e Ch 8: Virtual Machine II: Control | D9: Reading | G9: 2 | H9: Not started
A10: 5 | B10: N2T 8 | C10: Project 8 | D10: Lab/Project | F10: VM translator II: branching, function call/return, bootstrap | G10: 12 | H10: Not started
A11: 6 | B11: N2T 9 | C11: Read TECS 2e Ch 9: High-Level Language | D11: Reading | G11: 1 | H11: Not started
A12: 7 | B12: N2T 9 | C12: Project 9 | D12: Lab/Project | F12: Write a small Jack program (keep it small) | G12: 3 | H12: Not started
A13: 8 | B13: N2T 10 | C13: Read TECS 2e Ch 10: Compiler I: Syntax Analysis | D13: Reading | G13: 2 | H13: Not started
A14: 9 | B14: N2T 10 | C14: Project 10 | D14: Lab/Project | F14: Jack tokenizer + recursive-descent parser | G14: 11 | H14: Not started
A15: 10 | B15: N2T 11 | C15: Read TECS 2e Ch 11: Compiler II: Code Generation | D15: Reading | G15: 2.5 | H15: Not started
A16: 11 | B16: N2T 11 | C16: Project 11 | D16: Lab/Project | F16: Symbol tables and code generation to VM code | G16: 16 | H16: Not started
A17: 12 | B17: N2T 12 | C17: Read TECS 2e Ch 12: Operating System | D17: Reading | G17: 2 | H17: Not started
A18: 13 | B18: N2T 12 | C18: Project 12 | D18: Lab/Project | F18: The Jack OS: Math, Memory, String, Array, Screen, Output, Keyboard, Sys | G18: 13 | H18: Not started
A19: 14 | B19: CI | C19: Java ramp | D19: Setup | F19: Enough Java for jlox: classes, generics, enums, switch, exceptions. | G19: 4 | H19: Not started
A20: 15 | B20: CI 1 | C20: SKIM: Ch 1 Introduction | D20: Reading | F20: Quick read. | G20: 0.5 | H20: Not started
A21: 16 | B21: CI 2 | C21: Read: Ch 2 A Map of the Territory | D21: Reading | F21: CI Part I | G21: 1 | H21: Not started
A22: 17 | B22: CI 3 | C22: Read: Ch 3 The Lox Language | D22: Reading | F22: CI Part I | G22: 1 | H22: Not started
A23: 18 | B23: CI 4 | C23: SKIM: Ch 4 Scanning | D23: Reading | F23: Covered by N2T project 10. Skim, then copy the chapter's finished code from the book's repo. | G23: 1 | H23: Not started
A24: 19 | B24: CI 5 | C24: Read + build: Ch 5 Representing Code | D24: Reading | F24: CI Part II (jlox, Java) | G24: 3 | H24: Not started
A25: 20 | B25: CI 5 | C25: Challenge 5.3 | D25: Exercise | E25: 1 | F25: RPN printer visitor. Answers: the repo's note/answers folder. | G25: 1 | H25: Not started
A26: 21 | B26: CI 6 | C26: Read + build: Ch 6 Parsing Expressions | D26: Reading | F26: CI Part II (jlox, Java) | G26: 3 | H26: Not started
A27: 22 | B27: CI 6 | C27: Challenge 6.2 | D27: Exercise | E27: 1 | F27: Add the ?: ternary operator. Answers: the repo's note/answers folder. | G27: 1.5 | H27: Not started
A28: 23 | B28: CI 7 | C28: Read + build: Ch 7 Evaluating Expressions | D28: Reading | F28: CI Part II (jlox, Java) | G28: 2.5 | H28: Not started
A29: 24 | B29: CI 8 | C29: Read + build: Ch 8 Statements and State | D29: Reading | F29: CI Part II (jlox, Java) | G29: 3 | H29: Not started
A30: 25 | B30: CI 8 | C30: Challenge 8.2 | D30: Exercise | E30: 1 | F30: Runtime error for uninitialized variables. Answers: the repo's note/answers folder. | G30: 1 | H30: Not started
A31: 26 | B31: CI 9 | C31: Read + build: Ch 9 Control Flow | D31: Reading | F31: CI Part II (jlox, Java) | G31: 2 | H31: Not started
A32: 27 | B32: CI 9 | C32: Challenge 9.3 | D32: Exercise | E32: 1 | F32: Add break statements. Answers: the repo's note/answers folder. | G32: 1.5 | H32: Not started
A33: 28 | B33: CI 10 | C33: Read + build: Ch 10 Functions | D33: Reading | F33: CI Part II (jlox, Java) | G33: 3 | H33: Not started
A34: 29 | B34: CI 10 | C34: Challenge 10.2 | D34: Exercise | E34: 1 | F34: Anonymous function syntax. Answers: the repo's note/answers folder. | G34: 2 | H34: Not started
A35: 30 | B35: CI 11 | C35: Read + build: Ch 11 Resolving and Binding | D35: Reading | F35: CI Part II (jlox, Java) | G35: 3 | H35: Not started
A36: 31 | B36: CI 11 | C36: Challenge 11.3 | D36: Exercise | E36: 1 | F36: Report unused local variables. Answers: the repo's note/answers folder. | G36: 1.5 | H36: Not started
A37: 32 | B37: CI 12 | C37: Read + build: Ch 12 Classes | D37: Reading | F37: CI Part II (jlox, Java) | G37: 3 | H37: Not started
A38: 33 | B38: CI 12 | C38: Challenge 12.1 | D38: Exercise | E38: 1 | F38: Static (class) methods. Answers: the repo's note/answers folder. | G38: 1.5 | H38: Not started
A39: 34 | B39: CI 13 | C39: Read + build: Ch 13 Inheritance | D39: Reading | F39: CI Part II (jlox, Java) | G39: 2 | H39: Not started
A40: 35 | B40: CI 13 | C40: Challenge 13.2 | D40: Exercise | E40: 1 | F40: BETA-style inner() methods. Answers: the repo's note/answers folder. | G40: 2.5 | H40: Not started
A41: 36 | B41: CI 14 | C41: Read + build: Ch 14 Chunks of Bytecode | D41: Reading | F41: CI Part III (clox, C) | G41: 2.5 | H41: Not started
...

Sheet 6 Operating Systems
A1: 6 · Operating Systems — OSTEP (all) + MIT 6.1810 labs
A2: Operating Systems: Three Easy Pieces (free online) plus five MIT 6.1810 xv6 labs. Homework skipped for Ch 9, 10, 21, 33, 38, 41, 44, 45, 48–50.
A3: Planned hrs | B3: =SUM($G$6:$G$500)-SUMIFS($G$6:$G$500,$H$6:$H$500,"Skipped") -> 168.5 | C3: Done hrs | D3: =SUMIFS($G$6:$G$500,$H$6:$H$500,"Done") -> 0 | E3: % complete | F3: =IF(B3=0,0,D3/B3) -> 0 | G3: Problems done | H3: =SUMIFS($E$6:$E$500,$D$6:$D$500,"Exercise",$H$6:$H$500,"Done") -> 0 | I3: of | J3: =SUMIFS($E$6:$E$500,$D$6:$D$500,"Exercise")-SUMIFS($E$6:$E$500,$D$6:$D$500,"Exercise",$H$6:$H$500,"Skipped") -> 26
A5: # | B5: Chapter / Section | C5: Item | D5: Type | E5: Qty | F5: What & why | G5: Est. hrs | H5: Status | I5: Date done | J5: Actual hrs | K5: Notes
A6: 1 | B6: Setup | C6: Clone ostep-homework and ostep-projects | D6: Setup | F6: github.com/remzi-arpacidusseau/ostep-homework (simulators check answers with -c) and .../ostep-projects. | G6: 1 | H6: Not started
A7: 2 | B7: Intro | C7: Read OSTEP Ch 1–2 | D7: Reading | G7: 1 | H7: Not started
A8: 3 | B8: Virtualization | C8: Read Ch 3–11 (CPU virtualization) | D8: Reading | G8: 7 | H8: Not started
A9: 4 | B9: Ch 4 | C9: Ch 4 homework: process-run.py | D9: Exercise | E9: 1 | F9: Do every question in the chapter's homework. | G9: 1 | H9: Not started
A10: 5 | B10: Ch 5 | C10: Ch 5 homework: Process API (C code) | D10: Exercise | E10: 1 | F10: Do every question in the chapter's homework. | G10: 2.5 | H10: Not started
A11: 6 | B11: Ch 6 | C11: Ch 6 homework: Measure syscall and context-switch cost | D11: Exercise | E11: 1 | F11: Do every question in the chapter's homework. | G11: 1.5 | H11: Not started
A12: 7 | B12: Ch 7 | C12: Ch 7 homework: scheduler.py | D12: Exercise | E12: 1 | F12: Do every question in the chapter's homework. | G12: 1 | H12: Not started
A13: 8 | B13: Ch 8 | C13: Ch 8 homework: mlfq.py | D13: Exercise | E13: 1 | F13: Do every question in the chapter's homework. | G13: 1.5 | H13: Not started
A14: 9 | B14: Virtualization | C14: Read Ch 12–24 (memory virtualization) | D14: Reading | G14: 12 | H14: Not started
A15: 10 | B15: Ch 13 | C15: Ch 13 homework: Address spaces (memory-user, pmap) | D15: Exercise | E15: 1 | F15: Do every question in the chapter's homework. | G15: 1.5 | H15: Not started
A16: 11 | B16: Ch 14 | C16: Ch 14 homework: Memory API (gdb, valgrind) | D16: Exercise | E16: 1 | F16: Do every question in the chapter's homework. | G16: 1.5 | H16: Not started
A17: 12 | B17: Ch 15 | C17: Ch 15 homework: relocation.py | D17: Exercise | E17: 1 | F17: Do every question in the chapter's homework. | G17: 1 | H17: Not started
A18: 13 | B18: Ch 16 | C18: Ch 16 homework: segmentation.py | D18: Exercise | E18: 1 | F18: Do every question in the chapter's homework. | G18: 1 | H18: Not started
A19: 14 | B19: Ch 17 | C19: Ch 17 homework: malloc.py | D19: Exercise | E19: 1 | F19: Do every question in the chapter's homework. | G19: 1.5 | H19: Not started
A20: 15 | B20: Ch 18 | C20: Ch 18 homework: paging-linear-translate.py | D20: Exercise | E20: 1 | F20: Do every question in the chapter's homework. | G20: 1 | H20: Not started
A21: 16 | B21: Ch 19 | C21: Ch 19 homework: Measure TLB size and cost (tlb.c) | D21: Exercise | E21: 1 | F21: Do every question in the chapter's homework. | G21: 3 | H21: Not started
A22: 17 | B22: Ch 20 | C22: Ch 20 homework: paging-multilevel-translate.py | D22: Exercise | E22: 1 | F22: Do every question in the chapter's homework. | G22: 1.5 | H22: Not started
A23: 18 | B23: Ch 22 | C23: Ch 22 homework: paging-policy.py | D23: Exercise | E23: 1 | F23: Do every question in the chapter's homework. | G23: 1.5 | H23: Not started
A24: 19 | B24: Concurrency | C24: Read Ch 25–34 (concurrency) | D24: Reading | G24: 9 | H24: Not started
A25: 20 | B25: Ch 26 | C25: Ch 26 homework: x86.py threads | D25: Exercise | E25: 1 | F25: Do every question in the chapter's homework. | G25: 1.5 | H25: Not started
A26: 21 | B26: Ch 27 | C26: Ch 27 homework: Thread API with helgrind | D26: Exercise | E26: 1 | F26: Do every question in the chapter's homework. | G26: 1.5 | H26: Not started
A27: 22 | B27: Ch 28 | C27: Ch 28 homework: x86.py lock implementations | D27: Exercise | E27: 1 | F27: Do every question in the chapter's homework. | G27: 2 | H27: Not started
A28: 23 | B28: Ch 29 | C28: Ch 29 homework: Lock-based data structures (C) | D28: Exercise | E28: 1 | F28: Do every question in the chapter's homework. | G28: 3 | H28: Not started
A29: 24 | B29: Ch 30 | C29: Ch 30 homework: Condition variables (C) | D29: Exercise | E29: 1 | F29: Do every question in the chapter's homework. | G29: 2.5 | H29: Not started
A30: 25 | B30: Ch 31 | C30: Ch 31 homework: Semaphores (C) | D30: Exercise | E30: 1 | F30: Do every question in the chapter's homework. | G30: 3 | H30: Not started
A31: 26 | B31: Ch 32 | C31: Ch 32 homework: Deadlock (vector-deadlock) | D31: Exercise | E31: 1 | F31: Do every question in the chapter's homework. | G31: 2 | H31: Not started
A32: 27 | B32: Persistence | C32: Read Ch 35–46 (persistence) | D32: Reading | G32: 12 | H32: Not started
A33: 28 | B33: Ch 37 | C33: Ch 37 homework: disk.py | D33: Exercise | E33: 1 | F33: Do every question in the chapter's homework. | G33: 1.5 | H33: Not started
A34: 29 | B34: Ch 39 | C34: Ch 39 homework: Files and directories (C: stat, ls, tail, find) | D34: Exercise | E34: 1 | F34: Do every question in the chapter's homework. | G34: 3 | H34: Not started
A35: 30 | B35: Ch 40 | C35: Ch 40 homework: vsfs.py | D35: Exercise | E35: 1 | F35: Do every question in the chapter's homework. | G35: 1.5 | H35: Not started
A36: 31 | B36: Ch 42 | C36: Ch 42 homework: fsck.py | D36: Exercise | E36: 1 | F36: Do every question in the chapter's homework. | G36: 1.5 | H36: Not started
A37: 32 | B37: Ch 43 | C37: Ch 43 homework: lfs.py | D37: Exercise | E37: 1 | F37: Do every question in the chapter's homework. | G37: 1.5 | H37: Not started
A38: 33 | B38: Distribution | C38: Read Ch 47–51 (distribution) | D38: Reading | F38: DDIA and 6.5840 go deeper later. | G38: 4 | H38: Not started
A39: 34 | B39: Security | C39: Read Ch 52–57 (security) | D39: Reading | F39: Skim the cryptography chapter; MCS covered RSA. | G39: 5 | H39: Not started
A40: 35 | B40: Project | C40: OSTEP project: processes-shell (wish) | D40: Lab/Project | F40: Build a Unix shell: fork/exec/wait, paths, redirection, parallel commands. | G40: 10 | H40: Not started
A41: 36 | B41: 6.1810 | C41: Toolchain + xv6 setup | D41: Setup | F41: Follow the current semester's Tools page at pdos.csail.mit.edu/6.1810. | G41: 3 | H41: Not started
...

Sheet 7 Networking
A1: 7 · Computer Networking — Kurose & Ross 9th ed. + Wireshark 9.0
A2: Computer Networking: A Top-Down Approach, 9th ed. The free interactive problems are listed one per row; textbook-problem rows are a count per chapter. Wireshark lab solutions are instructor-only, so check your reasoning against the chapter.
A3: Planned hrs | B3: =SUM($G$6:$G$500)-SUMIFS($G$6:$G$500,$H$6:$H$500,"Skipped") -> 164.5 | C3: Done hrs | D3: =SUMIFS($G$6:$G$500,$H$6:$H$500,"Done") -> 0 | E3: % complete | F3: =IF(B3=0,0,D3/B3) -> 0 | G3: Problems done | H3: =SUMIFS($E$6:$E$500,$D$6:$D$500,"Exercise",$H$6:$H$500,"Done") -> 0 | I3: of | J3: =SUMIFS($E$6:$E$500,$D$6:$D$500,"Exercise")-SUMIFS($E$6:$E$500,$D$6:$D$500,"Exercise",$H$6:$H$500,"Skipped") -> 119
A5: # | B5: Chapter / Section | C5: Item | D5: Type | E5: Qty | F5: What & why | G5: Est. hrs | H5: Status | I5: Date done | J5: Actual hrs | K5: Notes
A6: 1 | B6: Setup | C6: Install Wireshark; bookmark companion resources | D6: Setup | F6: Interactive problems: gaia.cs.umass.edu/kurose_ross/interactive/ — Wireshark labs: .../kurose_ross/wireshark.php | G6: 0.5 | H6: Not started
A7: 2 | B7: Ch 1 | C7: Read Ch 1: Computer Networks and the Internet | D7: Reading | G7: 6 | H7: Not started
A8: 3 | B8: Ch 1 | C8: Interactive: Circuit Switching | D8: Exercise | E8: 1 | F8: Free and self-checking; generate a few instances until it's automatic. | G8: 0.3 | H8: Not started
A9: 4 | B9: Ch 1 | C9: Interactive: Packet vs. Circuit Switching (quantitative) | D9: Exercise | E9: 1 | F9: Free and self-checking; generate a few instances until it's automatic. | G9: 0.3 | H9: Not started
A10: 5 | B10: Ch 1 | C10: Interactive: Car–Caravan Analogy | D10: Exercise | E10: 1 | F10: Free and self-checking; generate a few instances until it's automatic. | G10: 0.3 | H10: Not started
A11: 6 | B11: Ch 1 | C11: Interactive: One-hop Transmission Delay | D11: Exercise | E11: 1 | F11: Free and self-checking; generate a few instances until it's automatic. | G11: 0.3 | H11: Not started
A12: 7 | B12: Ch 1 | C12: Interactive: Queuing Delay | D12: Exercise | E12: 1 | F12: Free and self-checking; generate a few instances until it's automatic. | G12: 0.3 | H12: Not started
A13: 8 | B13: Ch 1 | C13: Interactive: End-to-End Delay | D13: Exercise | E13: 1 | F13: Free and self-checking; generate a few instances until it's automatic. | G13: 0.3 | H13: Not started
A14: 9 | B14: Ch 1 | C14: Interactive: End-to-End Throughput | D14: Exercise | E14: 1 | F14: Free and self-checking; generate a few instances until it's automatic. | G14: 0.3 | H14: Not started
A15: 10 | B15: Ch 1 | C15: Interactive: The IP Stack and Protocol Layering | D15: Exercise | E15: 1 | F15: Free and self-checking; generate a few instances until it's automatic. | G15: 0.3 | H15: Not started
A16: 11 | B16: Ch 1 | C16: Ch 1 textbook problems ×8 | D16: Exercise | E16: 8 | F16: Favor problems the interactive set doesn't mirror (it notes which ones it mirrors) and the design/why questions. Log numbers in Notes. | G16: 4 | H16: Not started
A17: 12 | B17: Ch 1 | C17: Wireshark lab (v9.0): Getting Started | D17: Lab/Project | G17: 1 | H17: Not started
A18: 13 | B18: Ch 2 | C18: Read Ch 2: Application Layer | D18: Reading | G18: 8 | H18: Not started
A19: 14 | B19: Ch 2 | C19: Interactive: DNS – Basics | D19: Exercise | E19: 1 | F19: Free and self-checking; generate a few instances until it's automatic. | G19: 0.3 | H19: Not started
A20: 15 | B20: Ch 2 | C20: Interactive: DNS – Iterative vs. Recursive Query | D20: Exercise | E20: 1 | F20: Free and self-checking; generate a few instances until it's automatic. | G20: 0.3 | H20: Not started
A21: 16 | B21: Ch 2 | C21: Interactive: DNS and HTTP delays | D21: Exercise | E21: 1 | F21: Free and self-checking; generate a few instances until it's automatic. | G21: 0.3 | H21: Not started
A22: 17 | B22: Ch 2 | C22: Interactive: HTTP GET | D22: Exercise | E22: 1 | F22: Free and self-checking; generate a few instances until it's automatic. | G22: 0.3 | H22: Not started
A23: 18 | B23: Ch 2 | C23: Interactive: HTTP RESPONSE | D23: Exercise | E23: 1 | F23: Free and self-checking; generate a few instances until it's automatic. | G23: 0.3 | H23: Not started
A24: 19 | B24: Ch 2 | C24: Interactive: Browser Caching | D24: Exercise | E24: 1 | F24: Free and self-checking; generate a few instances until it's automatic. | G24: 0.3 | H24: Not started
A25: 20 | B25: Ch 2 | C25: Interactive: Electronic Mail and SMTP | D25: Exercise | E25: 1 | F25: Free and self-checking; generate a few instances until it's automatic. | G25: 0.3 | H25: Not started
